Traceback (most recent call last):
  File "/opt/hostedtoolcache/Python/3.7.10/x64/lib/python3.7/site-packages/jupyter_cache/executors/utils.py", line 56, in single_nb_execution
    record_timing=False,
  File "/opt/hostedtoolcache/Python/3.7.10/x64/lib/python3.7/site-packages/nbclient/client.py", line 1112, in execute
    return NotebookClient(nb=nb, resources=resources, km=km, **kwargs).execute()
  File "/opt/hostedtoolcache/Python/3.7.10/x64/lib/python3.7/site-packages/nbclient/util.py", line 74, in wrapped
    return just_run(coro(*args, **kwargs))
  File "/opt/hostedtoolcache/Python/3.7.10/x64/lib/python3.7/site-packages/nbclient/util.py", line 53, in just_run
    return loop.run_until_complete(coro)
  File "/opt/hostedtoolcache/Python/3.7.10/x64/lib/python3.7/asyncio/base_events.py", line 587, in run_until_complete
    return future.result()
  File "/opt/hostedtoolcache/Python/3.7.10/x64/lib/python3.7/site-packages/nbclient/client.py", line 554, in async_execute
    cell, index, execution_count=self.code_cells_executed + 1
  File "/opt/hostedtoolcache/Python/3.7.10/x64/lib/python3.7/site-packages/nbclient/client.py", line 857, in async_execute_cell
    self._check_raise_for_error(cell, exec_reply)
  File "/opt/hostedtoolcache/Python/3.7.10/x64/lib/python3.7/site-packages/nbclient/client.py", line 760, in _check_raise_for_error
    raise CellExecutionError.from_cell_and_msg(cell, exec_reply_content)
nbclient.exceptions.CellExecutionError: An error occurred while executing the following cell:
------------------
import warnings

warnings.filterwarnings("ignore")

from tempfile import mkstemp
from pathlib import Path
import requests

if dmri_dataset._filepath.exists():
    dmri_dataset._filepath.unlink()
url = "https://files.osf.io/v1/resources/8k95s/providers/osfstorage/6070b4c2f6585f03fb6123a2"
datapath = Path(mkstemp(suffix=".h5")[1])
if datapath.stat().st_size == 0:
    datapath.write_bytes(
        requests.get(url, allow_redirects=True).content
    )

dmri_dataset = DWI.from_filename(datapath)
dmri_dataset.dataobj = dmri_dataset.dataobj[..., :32]
dmri_dataset.gradients = dmri_dataset.gradients[..., :32]
datapath.unlink()
------------------

[0;31m---------------------------------------------------------------------------[0m
[0;31mNameError[0m                                 Traceback (most recent call last)
[0;32m<ipython-input-1-a662488204c5>[0m in [0;36m<module>[0;34m[0m
[1;32m      7[0m [0;32mimport[0m [0mrequests[0m[0;34m[0m[0;34m[0m[0m
[1;32m      8[0m [0;34m[0m[0m
[0;32m----> 9[0;31m [0;32mif[0m [0mdmri_dataset[0m[0;34m.[0m[0m_filepath[0m[0;34m.[0m[0mexists[0m[0;34m([0m[0;34m)[0m[0;34m:[0m[0;34m[0m[0;34m[0m[0m
[0m[1;32m     10[0m     [0mdmri_dataset[0m[0;34m.[0m[0m_filepath[0m[0;34m.[0m[0munlink[0m[0;34m([0m[0;34m)[0m[0;34m[0m[0;34m[0m[0m
[1;32m     11[0m [0murl[0m [0;34m=[0m [0;34m"https://files.osf.io/v1/resources/8k95s/providers/osfstorage/6070b4c2f6585f03fb6123a2"[0m[0;34m[0m[0;34m[0m[0m

[0;31mNameError[0m: name 'dmri_dataset' is not defined
NameError: name 'dmri_dataset' is not defined

