Traceback (most recent call last):
  File "/opt/hostedtoolcache/Python/3.7.10/x64/lib/python3.7/site-packages/jupyter_cache/executors/utils.py", line 56, in single_nb_execution
    record_timing=False,
  File "/opt/hostedtoolcache/Python/3.7.10/x64/lib/python3.7/site-packages/nbclient/client.py", line 1112, in execute
    return NotebookClient(nb=nb, resources=resources, km=km, **kwargs).execute()
  File "/opt/hostedtoolcache/Python/3.7.10/x64/lib/python3.7/site-packages/nbclient/util.py", line 74, in wrapped
    return just_run(coro(*args, **kwargs))
  File "/opt/hostedtoolcache/Python/3.7.10/x64/lib/python3.7/site-packages/nbclient/util.py", line 53, in just_run
    return loop.run_until_complete(coro)
  File "/opt/hostedtoolcache/Python/3.7.10/x64/lib/python3.7/asyncio/base_events.py", line 587, in run_until_complete
    return future.result()
  File "/opt/hostedtoolcache/Python/3.7.10/x64/lib/python3.7/site-packages/nbclient/client.py", line 554, in async_execute
    cell, index, execution_count=self.code_cells_executed + 1
  File "/opt/hostedtoolcache/Python/3.7.10/x64/lib/python3.7/site-packages/nbclient/client.py", line 857, in async_execute_cell
    self._check_raise_for_error(cell, exec_reply)
  File "/opt/hostedtoolcache/Python/3.7.10/x64/lib/python3.7/site-packages/nbclient/client.py", line 760, in _check_raise_for_error
    raise CellExecutionError.from_cell_and_msg(cell, exec_reply_content)
nbclient.exceptions.CellExecutionError: An error occurred while executing the following cell:
------------------
from pathlib import Path
from tempfile import mkdtemp
from eddymotion.estimator import _to_nifti

tempdir = Path(mkdtemp())

# The fixed image is our prediction
fixed_path = tempdir / "fixed.nii.gz"
_to_nifti(predicted, dmri_dataset.affine, fixed_path)

# The moving image is the left-out DW map
moving_path = tempdir / "moving.nii.gz"
_to_nifti(data_test[0], dmri_dataset.affine, moving_path)
------------------

[0;31m---------------------------------------------------------------------------[0m
[0;31mImportError[0m                               Traceback (most recent call last)
[0;32m<ipython-input-3-f9f54fccc673>[0m in [0;36m<module>[0;34m[0m
[1;32m      1[0m [0;32mfrom[0m [0mpathlib[0m [0;32mimport[0m [0mPath[0m[0;34m[0m[0;34m[0m[0m
[1;32m      2[0m [0;32mfrom[0m [0mtempfile[0m [0;32mimport[0m [0mmkdtemp[0m[0;34m[0m[0;34m[0m[0m
[0;32m----> 3[0;31m [0;32mfrom[0m [0meddymotion[0m[0;34m.[0m[0mestimator[0m [0;32mimport[0m [0m_to_nifti[0m[0;34m[0m[0;34m[0m[0m
[0m[1;32m      4[0m [0;34m[0m[0m
[1;32m      5[0m [0mtempdir[0m [0;34m=[0m [0mPath[0m[0;34m([0m[0mmkdtemp[0m[0;34m([0m[0;34m)[0m[0;34m)[0m[0;34m[0m[0;34m[0m[0m

[0;31mImportError[0m: cannot import name '_to_nifti' from 'eddymotion.estimator' (/opt/hostedtoolcache/Python/3.7.10/x64/lib/python3.7/site-packages/eddymotion/estimator.py)
ImportError: cannot import name '_to_nifti' from 'eddymotion.estimator' (/opt/hostedtoolcache/Python/3.7.10/x64/lib/python3.7/site-packages/eddymotion/estimator.py)

